[2024-11-01T15:01:26.088+0000] {taskinstance.py:1979} INFO - Dependencies all met for dep_context=non-requeueable deps ti=<TaskInstance: updating_stock_data.load_to_db scheduled__2024-09-30T00:00:00+00:00 [queued]>
[2024-11-01T15:01:26.095+0000] {taskinstance.py:1979} INFO - Dependencies all met for dep_context=requeueable deps ti=<TaskInstance: updating_stock_data.load_to_db scheduled__2024-09-30T00:00:00+00:00 [queued]>
[2024-11-01T15:01:26.096+0000] {taskinstance.py:2193} INFO - Starting attempt 1 of 2
[2024-11-01T15:01:26.107+0000] {taskinstance.py:2217} INFO - Executing <Task(_PythonDecoratedOperator): load_to_db> on 2024-09-30 00:00:00+00:00
[2024-11-01T15:01:26.114+0000] {standard_task_runner.py:60} INFO - Started process 3167 to run task
[2024-11-01T15:01:26.117+0000] {standard_task_runner.py:87} INFO - Running: ['airflow', 'tasks', 'run', 'updating_stock_data', 'load_to_db', 'scheduled__2024-09-30T00:00:00+00:00', '--job-id', '209', '--raw', '--subdir', 'DAGS_FOLDER/polars_postgres.py', '--cfg-path', '/tmp/tmppys5yaa5']
[2024-11-01T15:01:26.118+0000] {standard_task_runner.py:88} INFO - Job 209: Subtask load_to_db
[2024-11-01T15:01:26.164+0000] {task_command.py:423} INFO - Running <TaskInstance: updating_stock_data.load_to_db scheduled__2024-09-30T00:00:00+00:00 [running]> on host 07e6c451f8a5
[2024-11-01T15:01:26.233+0000] {taskinstance.py:2513} INFO - Exporting env vars: AIRFLOW_CTX_DAG_OWNER='airflow_development' AIRFLOW_CTX_DAG_ID='updating_stock_data' AIRFLOW_CTX_TASK_ID='load_to_db' AIRFLOW_CTX_EXECUTION_DATE='2024-09-30T00:00:00+00:00' AIRFLOW_CTX_TRY_NUMBER='1' AIRFLOW_CTX_DAG_RUN_ID='scheduled__2024-09-30T00:00:00+00:00'
[2024-11-01T15:01:26.235+0000] {logging_mixin.py:188} INFO - postgres urlNone
[2024-11-01T15:01:26.235+0000] {taskinstance.py:2731} ERROR - Task failed with exception
Traceback (most recent call last):
  File "/home/airflow/.local/lib/python3.8/site-packages/airflow/models/taskinstance.py", line 444, in _execute_task
    result = _execute_callable(context=context, **execute_callable_kwargs)
  File "/home/airflow/.local/lib/python3.8/site-packages/airflow/models/taskinstance.py", line 414, in _execute_callable
    return execute_callable(context=context, **execute_callable_kwargs)
  File "/home/airflow/.local/lib/python3.8/site-packages/airflow/decorators/base.py", line 241, in execute
    return_value = super().execute(context)
  File "/home/airflow/.local/lib/python3.8/site-packages/airflow/operators/python.py", line 200, in execute
    return_value = self.execute_callable()
  File "/home/airflow/.local/lib/python3.8/site-packages/airflow/operators/python.py", line 217, in execute_callable
    return self.python_callable(*self.op_args, **self.op_kwargs)
  File "/opt/airflow/dags/polars_postgres.py", line 126, in load_to_db
    raise ValueError("Database URL not found in environment variables")
ValueError: Database URL not found in environment variables
[2024-11-01T15:01:26.245+0000] {taskinstance.py:1149} INFO - Marking task as UP_FOR_RETRY. dag_id=updating_stock_data, task_id=load_to_db, execution_date=20240930T000000, start_date=20241101T150126, end_date=20241101T150126
[2024-11-01T15:01:26.254+0000] {standard_task_runner.py:107} ERROR - Failed to execute job 209 for task load_to_db (Database URL not found in environment variables; 3167)
[2024-11-01T15:01:26.289+0000] {local_task_job_runner.py:234} INFO - Task exited with return code 1
[2024-11-01T15:01:26.310+0000] {taskinstance.py:3312} INFO - 0 downstream tasks scheduled from follow-on schedule check
