[2024-11-01T15:28:46.561+0000] {taskinstance.py:1979} INFO - Dependencies all met for dep_context=non-requeueable deps ti=<TaskInstance: updating_stock_data.load_to_db scheduled__2024-09-30T00:00:00+00:00 [queued]>
[2024-11-01T15:28:46.603+0000] {taskinstance.py:1979} INFO - Dependencies all met for dep_context=requeueable deps ti=<TaskInstance: updating_stock_data.load_to_db scheduled__2024-09-30T00:00:00+00:00 [queued]>
[2024-11-01T15:28:46.605+0000] {taskinstance.py:2193} INFO - Starting attempt 8 of 9
[2024-11-01T15:28:46.654+0000] {taskinstance.py:2217} INFO - Executing <Task(_PythonDecoratedOperator): load_to_db> on 2024-09-30 00:00:00+00:00
[2024-11-01T15:28:46.671+0000] {standard_task_runner.py:60} INFO - Started process 4183 to run task
[2024-11-01T15:28:46.683+0000] {standard_task_runner.py:87} INFO - Running: ['airflow', 'tasks', 'run', 'updating_stock_data', 'load_to_db', 'scheduled__2024-09-30T00:00:00+00:00', '--job-id', '220', '--raw', '--subdir', 'DAGS_FOLDER/polars_postgres.py', '--cfg-path', '/tmp/tmpn3p39u0o']
[2024-11-01T15:28:46.687+0000] {standard_task_runner.py:88} INFO - Job 220: Subtask load_to_db
[2024-11-01T15:28:46.897+0000] {task_command.py:423} INFO - Running <TaskInstance: updating_stock_data.load_to_db scheduled__2024-09-30T00:00:00+00:00 [running]> on host 07e6c451f8a5
[2024-11-01T15:28:47.025+0000] {taskinstance.py:2513} INFO - Exporting env vars: AIRFLOW_CTX_DAG_OWNER='airflow_development' AIRFLOW_CTX_DAG_ID='updating_stock_data' AIRFLOW_CTX_TASK_ID='load_to_db' AIRFLOW_CTX_EXECUTION_DATE='2024-09-30T00:00:00+00:00' AIRFLOW_CTX_TRY_NUMBER='8' AIRFLOW_CTX_DAG_RUN_ID='scheduled__2024-09-30T00:00:00+00:00'
[2024-11-01T15:28:47.027+0000] {logging_mixin.py:188} INFO - postgres urlpostgresql://***:***@postgres:5432/***
[2024-11-01T15:28:47.612+0000] {logging_mixin.py:188} INFO - Database operation failed: (psycopg2.errors.UndefinedColumn) column "Date" of relation "stock_data" does not exist
LINE 1: INSERT INTO stock_data ("Date", "Open", "Close", "Low", "Hig...
                                ^

[SQL: INSERT INTO stock_data ("Date", "Open", "Close", "Low", "High") VALUES (%(Date)s, %(Open)s, %(Close)s, %(Low)s, %(High)s)]
[parameters: ({'Date': '2024-11-01', 'Open': 0.65776, 'Close': 0.65781, 'Low': 0.65556, 'High': 0.65913}, {'Date': '2024-10-31', 'Open': 0.65836, 'Close': 0.65816, 'Low': 0.65729, 'High': 0.65859}, {'Date': '2024-10-30', 'Open': 0.65728, 'Close': 0.65728, 'Low': 0.65405, 'High': 0.658}, {'Date': '2024-10-29', 'Open': 0.6563, 'Close': 0.6563, 'Low': 0.65374, 'High': 0.65954}, {'Date': '2024-10-28', 'Open': 0.65827, 'Close': 0.65827, 'Low': 0.65459, 'High': 0.6586}, {'Date': '2024-10-27', 'Open': 0.66034, 'Close': 0.66034, 'Low': 0.65801, 'High': 0.66111}, {'Date': '2024-10-24', 'Open': 0.6637, 'Close': 0.6637, 'Low': 0.66197, 'High': 0.6647}, {'Date': '2024-10-23', 'Open': 0.6636, 'Close': 0.6636, 'Low': 0.66233, 'High': 0.66618}  ... displaying 10 of 22 total bound parameter sets ...  {'Date': '2024-10-06', 'Open': 0.68006, 'Close': 0.68006, 'Low': 0.67589, 'High': 0.6812}, {'Date': '2024-10-03', 'Open': 0.68503, 'Close': 0.68503, 'Low': 0.67884, 'High': 0.6852})]
(Background on this error at: https://sqlalche.me/e/14/f405)
[2024-11-01T15:28:47.613+0000] {taskinstance.py:2731} ERROR - Task failed with exception
Traceback (most recent call last):
  File "/home/airflow/.local/lib/python3.8/site-packages/sqlalchemy/engine/base.py", line 1890, in _execute_context
    self.dialect.do_executemany(
  File "/home/airflow/.local/lib/python3.8/site-packages/sqlalchemy/dialects/postgresql/psycopg2.py", line 982, in do_executemany
    context._psycopg2_fetched_rows = xtras.execute_values(
  File "/home/airflow/.local/lib/python3.8/site-packages/psycopg2/extras.py", line 1299, in execute_values
    cur.execute(b''.join(parts))
psycopg2.errors.UndefinedColumn: column "Date" of relation "stock_data" does not exist
LINE 1: INSERT INTO stock_data ("Date", "Open", "Close", "Low", "Hig...
                                ^


The above exception was the direct cause of the following exception:

Traceback (most recent call last):
  File "/home/airflow/.local/lib/python3.8/site-packages/airflow/models/taskinstance.py", line 444, in _execute_task
    result = _execute_callable(context=context, **execute_callable_kwargs)
  File "/home/airflow/.local/lib/python3.8/site-packages/airflow/models/taskinstance.py", line 414, in _execute_callable
    return execute_callable(context=context, **execute_callable_kwargs)
  File "/home/airflow/.local/lib/python3.8/site-packages/airflow/decorators/base.py", line 241, in execute
    return_value = super().execute(context)
  File "/home/airflow/.local/lib/python3.8/site-packages/airflow/operators/python.py", line 200, in execute
    return_value = self.execute_callable()
  File "/home/airflow/.local/lib/python3.8/site-packages/airflow/operators/python.py", line 217, in execute_callable
    return self.python_callable(*self.op_args, **self.op_kwargs)
  File "/opt/airflow/dags/polars_postgres.py", line 147, in load_to_db
    final.write_database(
  File "/home/airflow/.local/lib/python3.8/site-packages/polars/dataframe/frame.py", line 4049, in write_database
    res: int | None = self.to_pandas(
  File "/home/airflow/.local/lib/python3.8/site-packages/pandas/core/generic.py", line 2878, in to_sql
    return sql.to_sql(
  File "/home/airflow/.local/lib/python3.8/site-packages/pandas/io/sql.py", line 769, in to_sql
    return pandas_sql.to_sql(
  File "/home/airflow/.local/lib/python3.8/site-packages/pandas/io/sql.py", line 1920, in to_sql
    total_inserted = sql_engine.insert_records(
  File "/home/airflow/.local/lib/python3.8/site-packages/pandas/io/sql.py", line 1470, in insert_records
    raise err
  File "/home/airflow/.local/lib/python3.8/site-packages/pandas/io/sql.py", line 1461, in insert_records
    return table.insert(chunksize=chunksize, method=method)
  File "/home/airflow/.local/lib/python3.8/site-packages/pandas/io/sql.py", line 1023, in insert
    num_inserted = exec_insert(conn, keys, chunk_iter)
  File "/home/airflow/.local/lib/python3.8/site-packages/pandas/io/sql.py", line 929, in _execute_insert
    result = conn.execute(self.table.insert(), data)
  File "/home/airflow/.local/lib/python3.8/site-packages/sqlalchemy/engine/base.py", line 1385, in execute
    return meth(self, multiparams, params, _EMPTY_EXECUTION_OPTS)
  File "/home/airflow/.local/lib/python3.8/site-packages/sqlalchemy/sql/elements.py", line 334, in _execute_on_connection
    return connection._execute_clauseelement(
  File "/home/airflow/.local/lib/python3.8/site-packages/sqlalchemy/engine/base.py", line 1577, in _execute_clauseelement
    ret = self._execute_context(
  File "/home/airflow/.local/lib/python3.8/site-packages/sqlalchemy/engine/base.py", line 1953, in _execute_context
    self._handle_dbapi_exception(
  File "/home/airflow/.local/lib/python3.8/site-packages/sqlalchemy/engine/base.py", line 2134, in _handle_dbapi_exception
    util.raise_(
  File "/home/airflow/.local/lib/python3.8/site-packages/sqlalchemy/util/compat.py", line 211, in raise_
    raise exception
  File "/home/airflow/.local/lib/python3.8/site-packages/sqlalchemy/engine/base.py", line 1890, in _execute_context
    self.dialect.do_executemany(
  File "/home/airflow/.local/lib/python3.8/site-packages/sqlalchemy/dialects/postgresql/psycopg2.py", line 982, in do_executemany
    context._psycopg2_fetched_rows = xtras.execute_values(
  File "/home/airflow/.local/lib/python3.8/site-packages/psycopg2/extras.py", line 1299, in execute_values
    cur.execute(b''.join(parts))
sqlalchemy.exc.ProgrammingError: (psycopg2.errors.UndefinedColumn) column "Date" of relation "stock_data" does not exist
LINE 1: INSERT INTO stock_data ("Date", "Open", "Close", "Low", "Hig...
                                ^

[SQL: INSERT INTO stock_data ("Date", "Open", "Close", "Low", "High") VALUES (%(Date)s, %(Open)s, %(Close)s, %(Low)s, %(High)s)]
[parameters: ({'Date': '2024-11-01', 'Open': 0.65776, 'Close': 0.65781, 'Low': 0.65556, 'High': 0.65913}, {'Date': '2024-10-31', 'Open': 0.65836, 'Close': 0.65816, 'Low': 0.65729, 'High': 0.65859}, {'Date': '2024-10-30', 'Open': 0.65728, 'Close': 0.65728, 'Low': 0.65405, 'High': 0.658}, {'Date': '2024-10-29', 'Open': 0.6563, 'Close': 0.6563, 'Low': 0.65374, 'High': 0.65954}, {'Date': '2024-10-28', 'Open': 0.65827, 'Close': 0.65827, 'Low': 0.65459, 'High': 0.6586}, {'Date': '2024-10-27', 'Open': 0.66034, 'Close': 0.66034, 'Low': 0.65801, 'High': 0.66111}, {'Date': '2024-10-24', 'Open': 0.6637, 'Close': 0.6637, 'Low': 0.66197, 'High': 0.6647}, {'Date': '2024-10-23', 'Open': 0.6636, 'Close': 0.6636, 'Low': 0.66233, 'High': 0.66618}  ... displaying 10 of 22 total bound parameter sets ...  {'Date': '2024-10-06', 'Open': 0.68006, 'Close': 0.68006, 'Low': 0.67589, 'High': 0.6812}, {'Date': '2024-10-03', 'Open': 0.68503, 'Close': 0.68503, 'Low': 0.67884, 'High': 0.6852})]
(Background on this error at: https://sqlalche.me/e/14/f405)
[2024-11-01T15:28:47.638+0000] {taskinstance.py:1149} INFO - Marking task as UP_FOR_RETRY. dag_id=updating_stock_data, task_id=load_to_db, execution_date=20240930T000000, start_date=20241101T152846, end_date=20241101T152847
[2024-11-01T15:28:47.656+0000] {standard_task_runner.py:107} ERROR - Failed to execute job 220 for task load_to_db ((psycopg2.errors.UndefinedColumn) column "Date" of relation "stock_data" does not exist
LINE 1: INSERT INTO stock_data ("Date", "Open", "Close", "Low", "Hig...
                                ^

[SQL: INSERT INTO stock_data ("Date", "Open", "Close", "Low", "High") VALUES (%(Date)s, %(Open)s, %(Close)s, %(Low)s, %(High)s)]
[parameters: ({'Date': '2024-11-01', 'Open': 0.65776, 'Close': 0.65781, 'Low': 0.65556, 'High': 0.65913}, {'Date': '2024-10-31', 'Open': 0.65836, 'Close': 0.65816, 'Low': 0.65729, 'High': 0.65859}, {'Date': '2024-10-30', 'Open': 0.65728, 'Close': 0.65728, 'Low': 0.65405, 'High': 0.658}, {'Date': '2024-10-29', 'Open': 0.6563, 'Close': 0.6563, 'Low': 0.65374, 'High': 0.65954}, {'Date': '2024-10-28', 'Open': 0.65827, 'Close': 0.65827, 'Low': 0.65459, 'High': 0.6586}, {'Date': '2024-10-27', 'Open': 0.66034, 'Close': 0.66034, 'Low': 0.65801, 'High': 0.66111}, {'Date': '2024-10-24', 'Open': 0.6637, 'Close': 0.6637, 'Low': 0.66197, 'High': 0.6647}, {'Date': '2024-10-23', 'Open': 0.6636, 'Close': 0.6636, 'Low': 0.66233, 'High': 0.66618}  ... displaying 10 of 22 total bound parameter sets ...  {'Date': '2024-10-06', 'Open': 0.68006, 'Close': 0.68006, 'Low': 0.67589, 'High': 0.6812}, {'Date': '2024-10-03', 'Open': 0.68503, 'Close': 0.68503, 'Low': 0.67884, 'High': 0.6852})]
(Background on this error at: https://sqlalche.me/e/14/f405); 4183)
[2024-11-01T15:28:47.702+0000] {local_task_job_runner.py:234} INFO - Task exited with return code 1
[2024-11-01T15:28:47.786+0000] {taskinstance.py:3312} INFO - 0 downstream tasks scheduled from follow-on schedule check
