[2024-11-01T13:54:05.071+0000] {taskinstance.py:1979} INFO - Dependencies all met for dep_context=non-requeueable deps ti=<TaskInstance: updating_stock_data.reformating_datas manual__2024-11-01T13:34:11.696229+00:00 [queued]>
[2024-11-01T13:54:05.080+0000] {taskinstance.py:1979} INFO - Dependencies all met for dep_context=requeueable deps ti=<TaskInstance: updating_stock_data.reformating_datas manual__2024-11-01T13:34:11.696229+00:00 [queued]>
[2024-11-01T13:54:05.081+0000] {taskinstance.py:2193} INFO - Starting attempt 2 of 2
[2024-11-01T13:54:05.094+0000] {taskinstance.py:2217} INFO - Executing <Task(_PythonDecoratedOperator): reformating_datas> on 2024-11-01 13:34:11.696229+00:00
[2024-11-01T13:54:05.099+0000] {standard_task_runner.py:60} INFO - Started process 516 to run task
[2024-11-01T13:54:05.102+0000] {standard_task_runner.py:87} INFO - Running: ['airflow', 'tasks', 'run', 'updating_stock_data', 'reformating_datas', 'manual__2024-11-01T13:34:11.696229+00:00', '--job-id', '156', '--raw', '--subdir', 'DAGS_FOLDER/polars_postgres.py', '--cfg-path', '/tmp/tmpo3q0x695']
[2024-11-01T13:54:05.104+0000] {standard_task_runner.py:88} INFO - Job 156: Subtask reformating_datas
[2024-11-01T13:54:05.158+0000] {task_command.py:423} INFO - Running <TaskInstance: updating_stock_data.reformating_datas manual__2024-11-01T13:34:11.696229+00:00 [running]> on host 07e6c451f8a5
[2024-11-01T13:54:05.239+0000] {taskinstance.py:2513} INFO - Exporting env vars: AIRFLOW_CTX_DAG_OWNER='airflow_development' AIRFLOW_CTX_DAG_ID='updating_stock_data' AIRFLOW_CTX_TASK_ID='reformating_datas' AIRFLOW_CTX_EXECUTION_DATE='2024-11-01T13:34:11.696229+00:00' AIRFLOW_CTX_TRY_NUMBER='2' AIRFLOW_CTX_DAG_RUN_ID='manual__2024-11-01T13:34:11.696229+00:00'
[2024-11-01T13:54:05.242+0000] {logging_mixin.py:188} INFO - Error in data reformatting: unable to find column "Date"; valid columns: []
[2024-11-01T13:54:05.243+0000] {taskinstance.py:2731} ERROR - Task failed with exception
Traceback (most recent call last):
  File "/home/airflow/.local/lib/python3.8/site-packages/airflow/models/taskinstance.py", line 444, in _execute_task
    result = _execute_callable(context=context, **execute_callable_kwargs)
  File "/home/airflow/.local/lib/python3.8/site-packages/airflow/models/taskinstance.py", line 414, in _execute_callable
    return execute_callable(context=context, **execute_callable_kwargs)
  File "/home/airflow/.local/lib/python3.8/site-packages/airflow/decorators/base.py", line 241, in execute
    return_value = super().execute(context)
  File "/home/airflow/.local/lib/python3.8/site-packages/airflow/operators/python.py", line 200, in execute
    return_value = self.execute_callable()
  File "/home/airflow/.local/lib/python3.8/site-packages/airflow/operators/python.py", line 217, in execute_callable
    return self.python_callable(*self.op_args, **self.op_kwargs)
  File "/opt/airflow/dags/polars_postgres.py", line 51, in reformating_datas
    if result.collect().shape[0] == 0:
  File "/home/airflow/.local/lib/python3.8/site-packages/polars/lazyframe/frame.py", line 2053, in collect
    return wrap_df(ldf.collect(callback))
polars.exceptions.ColumnNotFoundError: unable to find column "Date"; valid columns: []
[2024-11-01T13:54:05.257+0000] {taskinstance.py:1149} INFO - Marking task as FAILED. dag_id=updating_stock_data, task_id=reformating_datas, execution_date=20241101T133411, start_date=20241101T135405, end_date=20241101T135405
[2024-11-01T13:54:05.267+0000] {standard_task_runner.py:107} ERROR - Failed to execute job 156 for task reformating_datas (unable to find column "Date"; valid columns: []; 516)
[2024-11-01T13:54:05.275+0000] {local_task_job_runner.py:234} INFO - Task exited with return code 1
[2024-11-01T13:54:05.300+0000] {taskinstance.py:3312} INFO - 0 downstream tasks scheduled from follow-on schedule check
