[2024-11-01T14:03:31.650+0000] {taskinstance.py:1979} INFO - Dependencies all met for dep_context=non-requeueable deps ti=<TaskInstance: updating_stock_data.reformating_datas scheduled__2024-09-30T00:00:00+00:00 [queued]>
[2024-11-01T14:03:31.659+0000] {taskinstance.py:1979} INFO - Dependencies all met for dep_context=requeueable deps ti=<TaskInstance: updating_stock_data.reformating_datas scheduled__2024-09-30T00:00:00+00:00 [queued]>
[2024-11-01T14:03:31.660+0000] {taskinstance.py:2193} INFO - Starting attempt 3 of 4
[2024-11-01T14:03:31.673+0000] {taskinstance.py:2217} INFO - Executing <Task(_PythonDecoratedOperator): reformating_datas> on 2024-09-30 00:00:00+00:00
[2024-11-01T14:03:31.678+0000] {standard_task_runner.py:60} INFO - Started process 869 to run task
[2024-11-01T14:03:31.680+0000] {standard_task_runner.py:87} INFO - Running: ['airflow', 'tasks', 'run', 'updating_stock_data', 'reformating_datas', 'scheduled__2024-09-30T00:00:00+00:00', '--job-id', '161', '--raw', '--subdir', 'DAGS_FOLDER/polars_postgres.py', '--cfg-path', '/tmp/tmpi53i8ohk']
[2024-11-01T14:03:31.681+0000] {standard_task_runner.py:88} INFO - Job 161: Subtask reformating_datas
[2024-11-01T14:03:31.731+0000] {task_command.py:423} INFO - Running <TaskInstance: updating_stock_data.reformating_datas scheduled__2024-09-30T00:00:00+00:00 [running]> on host 07e6c451f8a5
[2024-11-01T14:03:31.807+0000] {taskinstance.py:2513} INFO - Exporting env vars: AIRFLOW_CTX_DAG_OWNER='airflow_development' AIRFLOW_CTX_DAG_ID='updating_stock_data' AIRFLOW_CTX_TASK_ID='reformating_datas' AIRFLOW_CTX_EXECUTION_DATE='2024-09-30T00:00:00+00:00' AIRFLOW_CTX_TRY_NUMBER='3' AIRFLOW_CTX_DAG_RUN_ID='scheduled__2024-09-30T00:00:00+00:00'
[2024-11-01T14:03:31.809+0000] {logging_mixin.py:188} INFO - Error in data reformatting: No valid data found in the API response.
[2024-11-01T14:03:31.810+0000] {taskinstance.py:2731} ERROR - Task failed with exception
Traceback (most recent call last):
  File "/home/airflow/.local/lib/python3.8/site-packages/airflow/models/taskinstance.py", line 444, in _execute_task
    result = _execute_callable(context=context, **execute_callable_kwargs)
  File "/home/airflow/.local/lib/python3.8/site-packages/airflow/models/taskinstance.py", line 414, in _execute_callable
    return execute_callable(context=context, **execute_callable_kwargs)
  File "/home/airflow/.local/lib/python3.8/site-packages/airflow/decorators/base.py", line 241, in execute
    return_value = super().execute(context)
  File "/home/airflow/.local/lib/python3.8/site-packages/airflow/operators/python.py", line 200, in execute
    return_value = self.execute_callable()
  File "/home/airflow/.local/lib/python3.8/site-packages/airflow/operators/python.py", line 217, in execute_callable
    return self.python_callable(*self.op_args, **self.op_kwargs)
  File "/opt/airflow/dags/polars_postgres.py", line 51, in reformating_datas
    raise ValueError("No valid data found in the API response.")
ValueError: No valid data found in the API response.
[2024-11-01T14:03:31.821+0000] {taskinstance.py:1149} INFO - Marking task as UP_FOR_RETRY. dag_id=updating_stock_data, task_id=reformating_datas, execution_date=20240930T000000, start_date=20241101T140331, end_date=20241101T140331
[2024-11-01T14:03:31.835+0000] {standard_task_runner.py:107} ERROR - Failed to execute job 161 for task reformating_datas (No valid data found in the API response.; 869)
[2024-11-01T14:03:31.853+0000] {local_task_job_runner.py:234} INFO - Task exited with return code 1
[2024-11-01T14:03:31.884+0000] {taskinstance.py:3312} INFO - 0 downstream tasks scheduled from follow-on schedule check
