[2024-11-01T15:16:41.213+0000] {taskinstance.py:1979} INFO - Dependencies all met for dep_context=non-requeueable deps ti=<TaskInstance: updating_stock_data.final_transformation scheduled__2024-09-30T00:00:00+00:00 [queued]>
[2024-11-01T15:16:41.252+0000] {taskinstance.py:1979} INFO - Dependencies all met for dep_context=requeueable deps ti=<TaskInstance: updating_stock_data.final_transformation scheduled__2024-09-30T00:00:00+00:00 [queued]>
[2024-11-01T15:16:41.255+0000] {taskinstance.py:2193} INFO - Starting attempt 5 of 6
[2024-11-01T15:16:41.313+0000] {taskinstance.py:2217} INFO - Executing <Task(_PythonDecoratedOperator): final_transformation> on 2024-09-30 00:00:00+00:00
[2024-11-01T15:16:41.328+0000] {standard_task_runner.py:60} INFO - Started process 3716 to run task
[2024-11-01T15:16:41.339+0000] {standard_task_runner.py:87} INFO - Running: ['airflow', 'tasks', 'run', 'updating_stock_data', 'final_transformation', 'scheduled__2024-09-30T00:00:00+00:00', '--job-id', '213', '--raw', '--subdir', 'DAGS_FOLDER/polars_postgres.py', '--cfg-path', '/tmp/tmpbp8u8u6n']
[2024-11-01T15:16:41.343+0000] {standard_task_runner.py:88} INFO - Job 213: Subtask final_transformation
[2024-11-01T15:16:41.531+0000] {task_command.py:423} INFO - Running <TaskInstance: updating_stock_data.final_transformation scheduled__2024-09-30T00:00:00+00:00 [running]> on host 07e6c451f8a5
[2024-11-01T15:16:41.886+0000] {taskinstance.py:2513} INFO - Exporting env vars: AIRFLOW_CTX_DAG_OWNER='airflow_development' AIRFLOW_CTX_DAG_ID='updating_stock_data' AIRFLOW_CTX_TASK_ID='final_transformation' AIRFLOW_CTX_EXECUTION_DATE='2024-09-30T00:00:00+00:00' AIRFLOW_CTX_TRY_NUMBER='5' AIRFLOW_CTX_DAG_RUN_ID='scheduled__2024-09-30T00:00:00+00:00'
[2024-11-01T15:16:41.899+0000] {taskinstance.py:2731} ERROR - Task failed with exception
Traceback (most recent call last):
  File "/home/airflow/.local/lib/python3.8/site-packages/airflow/models/taskinstance.py", line 444, in _execute_task
    result = _execute_callable(context=context, **execute_callable_kwargs)
  File "/home/airflow/.local/lib/python3.8/site-packages/airflow/models/taskinstance.py", line 414, in _execute_callable
    return execute_callable(context=context, **execute_callable_kwargs)
  File "/home/airflow/.local/lib/python3.8/site-packages/airflow/decorators/base.py", line 241, in execute
    return_value = super().execute(context)
  File "/home/airflow/.local/lib/python3.8/site-packages/airflow/operators/python.py", line 200, in execute
    return_value = self.execute_callable()
  File "/home/airflow/.local/lib/python3.8/site-packages/airflow/operators/python.py", line 217, in execute_callable
    return self.python_callable(*self.op_args, **self.op_kwargs)
  File "/opt/airflow/dags/polars_postgres.py", line 114, in final_transformation
    pl.col('Date').str.strptime(pl.Date, fmt='%Y-%m-%d'),
TypeError: strptime() got an unexpected keyword argument 'fmt'
[2024-11-01T15:16:41.939+0000] {taskinstance.py:1149} INFO - Marking task as UP_FOR_RETRY. dag_id=updating_stock_data, task_id=final_transformation, execution_date=20240930T000000, start_date=20241101T151641, end_date=20241101T151641
[2024-11-01T15:16:41.994+0000] {standard_task_runner.py:107} ERROR - Failed to execute job 213 for task final_transformation (strptime() got an unexpected keyword argument 'fmt'; 3716)
[2024-11-01T15:16:42.037+0000] {local_task_job_runner.py:234} INFO - Task exited with return code 1
[2024-11-01T15:16:42.119+0000] {taskinstance.py:3312} INFO - 0 downstream tasks scheduled from follow-on schedule check
